Workbook
Name NativeTimeline_Issue_Date: #N/A
Name Slicer_Department: #N/A

Sheet Dashboard 

Sheet Analysis
A1: Show Aouther All Book
A3: Select Aouther | B3: Paulo Coelho
A5: Transaction ID | B5: Book ID | C5: Book Title | D5: Author | E5: Category | F5: Member ID | G5: Member Name | H5: Member Type | I5: Department | J5: Issue Date | K5: Due Date | L5: Return Date | M5: Days | N5: Return Book | O5: Month
A6: {=_xlfn._xlws.FILTER(Data[],Data[Author]=Analysis!B3,"Not Found")} -> 5023 | B6: 102 | C6: The Alchemist | D6: Paulo Coelho | E6: Fiction | F6: 2011 | G6: Ishaan Pandya | H6: Student | I6: Computer Science | J6: 46070 | K6: 46084 | L6: 46082 | M6: 14 | N6: Late Return | O6: February
A7: 5053 | B7: 102 | C7: The Alchemist | D7: Paulo Coelho | E7: Fiction | F7: 2007 | G7: Advik Shah | H7: Faculty | I7: Mathematics | J7: 46136 | K7: 46157 | L7: 46155 | M7: 21 | N7: Late Return | O7: April
A8: 5083 | B8: 102 | C8: The Alchemist | D8: Paulo Coelho | E8: Fiction | F8: 2003 | G8: Vivaan Mehta | H8: Faculty | I8: Computer Science | J8: 46202 | K8: 46209 | L8: 46207 | M8: 7 | N8: Late Return | O8: June
A9: 5113 | B9: 102 | C9: The Alchemist | D9: Paulo Coelho | E9: Fiction | F9: 2019 | G9: Rudra Gohil | H9: Student | I9: Science | J9: 46247 | K9: 46254 | L9: 46252 | M9: 7 | N9: Late Return | O9: August
A18: Find Transactions Info
A20: Select Transactions Id | B20: 5001
A22: Transaction ID | B22: {=TRANSPOSE(_xlfn.XLOOKUP($B$20,Data[Transaction ID],Data[]))} -> 5001
A23: Book ID | B23: 101
A24: Book Title | B24: Wings of Fire
A25: Author | B25: A. P. J. Abdul Kalam
A26: Category | B26: Biography
A27: Member ID | B27: 2001
A28: Member Name | B28: Aarav Shah
A29: Member Type | B29: Student
A30: Department | B30: Science
A31: Issue Date | B31: 46023
A32: Due Date | B32: 46030
A33: Return Date | B33: 46030
A34: Days | B34: 7
A35: Return Book | B35: Return Book
A36: Month | B36: January
A39: Show Book Status By Transaction
A41: Select Transction Id | B41: 5002
A43: Transction Id | B43: =VLOOKUP($B$41,Data[],1,FALSE) -> 5002
A44: Book Name | B44: =VLOOKUP($B$41,Data[],3,FALSE) -> Sapiens
A45: Return Status | B45: =VLOOKUP($B$41,Data[],14,FALSE) -> Late Return
A51: Month By Transactions
A53: Month | B53: Total Transactions | C53: Growth
A54: {=_xlfn.UNIQUE(Data[Month])} -> January | B54: =COUNTIF(Data[Month],Analysis!$A54) -> 12 | C54: -
A55: February | B55: =COUNTIF(Data[Month],Analysis!$A55) -> 14 | C55: =(B55-B54)/B54 -> 0.16666667
A56: March | B56: =COUNTIF(Data[Month],Analysis!$A56) -> 15 | C56: =(B56-B55)/B55 -> 0.071428571
A57: April | B57: =COUNTIF(Data[Month],Analysis!$A57) -> 15 | C57: =(B57-B56)/B56 -> 0
A58: May | B58: =COUNTIF(Data[Month],Analysis!$A58) -> 15 | C58: =(B58-B57)/B57 -> 0
A59: June | B59: =COUNTIF(Data[Month],Analysis!$A59) -> 15 | C59: =(B59-B58)/B58 -> 0
A60: July | B60: =COUNTIF(Data[Month],Analysis!$A60) -> 16 | C60: =(B60-B59)/B59 -> 0.066666667
A61: August | B61: =COUNTIF(Data[Month],Analysis!$A61) -> 15 | C61: =(B61-B60)/B60 -> -0.0625
A62: September | B62: =COUNTIF(Data[Month],Analysis!$A62) -> 3 | C62: =(B62-B61)/B61 -> -0.8
...

Sheet Summery Report

Sheet Pivot Tables
A2: Total Book Transction | D2: Member Type | E2: MemberType | H2: Member | I2: Transction | L2: Category | M2: Count Transction
A3: 607260 | D3: Faculty | E3: 0.30769231 | H3: Anvi Thakkar | I3: 3 | L3: Classic | M3: 4
D4: Student | E4: 0.69230769 | H4: Ishaan Pandya | I4: 3 | L4: Fantasy | M4: 2
H5: Saanvi Trivedi | I5: 3 | L5: Fiction | M5: 2
A6: Total Book | H6: Vivaan Mehta | I6: 4 | L6: Finance | M6: 2
A7: 120 | D7: Transction | E7: Book | L7: History | M7: 1
D8: 5008 | E8: 1 | L8: Self-help | M8: 1
D9: 5009 | E9: 1 | L9: Technology | M9: 1
A10: Average Borrowing Days | D10: 5019 | E10: 1 | H10: Book | I10: Transaction
A11: 15.216667 | D11: 5023 | E11: 1 | H11: Atomic Habits | I11: 1
D12: 5033 | E12: 1 | H12: Clean Code | I12: 1
D13: 5034 | E13: 1 | H13: Harry Potter and the Philosopher's Stone | I13: 1
D14: 5044 | E14: 1 | H14: India After Gandhi | I14: 1 | L14: Return Status | M14: ReturnBook
D15: 5048 | E15: 1 | H15: Pride and Prejudice | I15: 3 | L15: Late Return | M15: 0.69230769
D16: 5058 | E16: 1 | H16: Rich Dad Poor Dad | I16: 1 | L16: Return Book | M16: 0.30769231
D17: 5059 | E17: 1 | H17: The Alchemist | I17: 2
D18: 5069 | E18: 1 | H18: The Great Gatsby | I18: 1
D19: 5073 | E19: 1 | H19: The Hobbit | I19: 1
D20: 5083 | E20: 1 | H20: The Psychology of Money | I20: 1

Sheet Book Transction
A1: Transaction ID | B1: Book ID | C1: Book Title | D1: Author | E1: Category | F1: Member ID | G1: Member Name | H1: Member Type | I1: Department | J1: Issue Date | K1: Due Date | L1: Return Date | M1: Days | N1: Return Book | O1: Month
A2: 5001 | B2: 101 | C2: Wings of Fire | D2: A. P. J. Abdul Kalam | E2: Biography | F2: 2001 | G2: Aarav Shah | H2: Student | I2: Science | J2: 46023 | K2: 46030 | L2: 46030 | M2: =DATEDIF(Data[[#This Row],[Issue Date]],Data[[#This Row],[Due Date]],"d") -> 7 | N2: =IF(Data[[#This Row],[Due Date]]<>Data[[#This Row],[Return Date]],"Late Return","Return Book") -> Return Book | O2: =TEXT(Data[[#This Row],[Issue Date]],"mmmm") -> January
A3: 5002 | B3: 108 | C3: Sapiens | D3: Yuval Noah Harari | E3: History | F3: 2004 | G3: Anaya Desai | H3: Student | I3: Arts | J3: 46028 | K3: 46042 | L3: 46041 | M3: =DATEDIF(Data[[#This Row],[Issue Date]],Data[[#This Row],[Due Date]],"d") -> 14 | N3: =IF(Data[[#This Row],[Due Date]]<>Data[[#This Row],[Return Date]],"Late Return","Return Book") -> Late Return | O3: =TEXT(Data[[#This Row],[Issue Date]],"mmmm") -> January
A4: 5003 | B4: 115 | C4: The Psychology of Money | D4: Morgan Housel | E4: Finance | F4: 2007 | G4: Advik Shah | H4: Faculty | I4: Mathematics | J4: 46033 | K4: 46047 | L4: 46045 | M4: =DATEDIF(Data[[#This Row],[Issue Date]],Data[[#This Row],[Due Date]],"d") -> 14 | N4: =IF(Data[[#This Row],[Due Date]]<>Data[[#This Row],[Return Date]],"Late Return","Return Book") -> Late Return | O4: =TEXT(Data[[#This Row],[Issue Date]],"mmmm") -> January
A5: 5004 | B5: 103 | C5: Rich Dad Poor Dad | D5: Robert T. Kiyosaki | E5: Finance | F5: 2010 | G5: Kiara Bhatt | H5: Staff | I5: Library Services | J5: 46038 | K5: 46059 | L5: 46056 | M5: =DATEDIF(Data[[#This Row],[Issue Date]],Data[[#This Row],[Due Date]],"d") -> 21 | N5: =IF(Data[[#This Row],[Due Date]]<>Data[[#This Row],[Return Date]],"Late Return","Return Book") -> Late Return | O5: =TEXT(Data[[#This Row],[Issue Date]],"mmmm") -> January
A6: 5005 | B6: 110 | C6: Think and Grow Rich | D6: Napoleon Hill | E6: Finance | F6: 2013 | G6: Krish Solanki | H6: Student | I6: Arts | J6: 46043 | K6: 46057 | L6: 46053 | M6: =DATEDIF(Data[[#This Row],[Issue Date]],Data[[#This Row],[Due Date]],"d") -> 14 | N6: =IF(Data[[#This Row],[Due Date]]<>Data[[#This Row],[Return Date]],"Late Return","Return Book") -> Late Return | O6: =TEXT(Data[[#This Row],[Issue Date]],"mmmm") -> January
A7: 5006 | B7: 117 | C7: The Power of Now | D7: Eckhart Tolle | E7: Self-help | F7: 2017 | G7: Kabir Modi | H7: Faculty | I7: History | J7: 46048 | K7: 46055 | L7: 46056 | M7: =DATEDIF(Data[[#This Row],[Issue Date]],Data[[#This Row],[Due Date]],"d") -> 7 | N7: =IF(Data[[#This Row],[Due Date]]<>Data[[#This Row],[Return Date]],"Late Return","Return Book") -> Late Return | O7: =TEXT(Data[[#This Row],[Issue Date]],"mmmm") -> January
A8: 5007 | B8: 105 | C8: Harry Potter and the Philosopher's Stone | D8: J. K. Rowling | E8: Fantasy | F8: 2020 | G8: Sara Merchant | H8: Student | I8: Arts | J8: 46053 | K8: 46083 | L8: 46087 | M8: =DATEDIF(Data[[#This Row],[Issue Date]],Data[[#This Row],[Due Date]],"d") -> 30 | N8: =IF(Data[[#This Row],[Due Date]]<>Data[[#This Row],[Return Date]],"Late Return","Return Book") -> Late Return | O8: =TEXT(Data[[#This Row],[Issue Date]],"mmmm") -> January
A9: 5008 | B9: 112 | C9: Clean Code | D9: Robert C. Martin | E9: Technology | F9: 2003 | G9: Vivaan Mehta | H9: Faculty | I9: Computer Science | J9: 46037 | K9: 46044 | L9: 46049 | M9: =DATEDIF(Data[[#This Row],[Issue Date]],Data[[#This Row],[Due Date]],"d") -> 7 | N9: =IF(Data[[#This Row],[Due Date]]<>Data[[#This Row],[Return Date]],"Late Return","Return Book") -> Late Return | O9: =TEXT(Data[[#This Row],[Issue Date]],"mmmm") -> January
A10: 5009 | B10: 119 | C10: Pride and Prejudice | D10: Jane Austen | E10: Classic | F10: 2006 | G10: Saanvi Trivedi | H10: Student | I10: Computer Science | J10: 46042 | K10: 46056 | L10: 46061 | M10: =DATEDIF(Data[[#This Row],[Issue Date]],Data[[#This Row],[Due Date]],"d") -> 14 | N10: =IF(Data[[#This Row],[Due Date]]<>Data[[#This Row],[Return Date]],"Late Return","Return Book") -> Late Return | O10: =TEXT(Data[[#This Row],[Issue Date]],"mmmm") -> January
A11: 5010 | B11: 107 | C11: Ikigai | D11: Héctor García and Francesc Miralles | E11: Self-help | F11: 2009 | G11: Arjun Vyas | H11: Student | I11: Commerce | J11: 46047 | K11: 46061 | L11: 46071 | M11: =DATEDIF(Data[[#This Row],[Issue Date]],Data[[#This Row],[Due Date]],"d") -> 14 | N11: =IF(Data[[#This Row],[Due Date]]<>Data[[#This Row],[Return Date]],"Late Return","Return Book") -> Late Return | O11: =TEXT(Data[[#This Row],[Issue Date]],"mmmm") -> January
A12: 5011 | B12: 114 | C12: To Kill a Mockingbird | D12: Harper Lee | E12: Classic | F12: 2013 | G12: Krish Solanki | H12: Student | I12: Arts | J12: 46052 | K12: 46073 | L12: 46074 | M12: =DATEDIF(Data[[#This Row],[Issue Date]],Data[[#This Row],[Due Date]],"d") -> 21 | N12: =IF(Data[[#This Row],[Due Date]]<>Data[[#This Row],[Return Date]],"Late Return","Return Book") -> Late Return | O12: =TEXT(Data[[#This Row],[Issue Date]],"mmmm") -> January
A13: 5012 | B13: 101 | C13: Wings of Fire | D13: A. P. J. Abdul Kalam | E13: Biography | F13: 2016 | G13: Navya Dave | H13: Student | I13: Commerce | J13: 46057 | K13: 46071 | L13: 46070 | M13: =DATEDIF(Data[[#This Row],[Issue Date]],Data[[#This Row],[Due Date]],"d") -> 14 | N13: =IF(Data[[#This Row],[Due Date]]<>Data[[#This Row],[Return Date]],"Late Return","Return Book") -> Late Return | O13: =TEXT(Data[[#This Row],[Issue Date]],"mmmm") -> February
... A121: 5120 | B121: 113 | C121: The Hobbit | D121: J. R. R. Tolkien | E121: Fantasy | F121: 2001 | G121: Aarav Shah | H121: Student | I121: Science | J121: 46261 | K121: 46268 | L121: 46268 | M121: =DATEDIF(Data[[#This Row],[Issue Date]],Data[[#This Row],[Due Date]],"d") -> 7 | N121: =IF(Data[[#This Row],[Due Date]]<>Data[[#This Row],[Return Date]],"Late Return","Return Book") -> Return Book | O121: =TEXT(Data[[#This Row],[Issue Date]],"mmmm") -> August
